[ERROR] 2025-02-12 15:02:42,453 - member_system_logger - ERROR - 查询出错: 
        SELECT * FROM chats
        WHERE rule_group_id = %s
        ORDER BY created_at DESC
        , (1054, "Unknown column 'rule_group_id' in 'where clause'")
Traceback (most recent call last):
  File "/root/kimi-dev/telegram-moderation-bot/src/core/database/db/base_database.py", line 97, in fetch_all
    await cursor.execute(sql, params)
  File "/root/kimi-dev/telegram-moderation-bot/venv/lib/python3.10/site-packages/aiomysql/cursors.py", line 239, in execute
    await self._query(query)
  File "/root/kimi-dev/telegram-moderation-bot/venv/lib/python3.10/site-packages/aiomysql/cursors.py", line 457, in _query
    await conn.query(q)
  File "/root/kimi-dev/telegram-moderation-bot/venv/lib/python3.10/site-packages/aiomysql/connection.py", line 469, in query
    await self._read_query_result(unbuffered=unbuffered)
  File "/root/kimi-dev/telegram-moderation-bot/venv/lib/python3.10/site-packages/aiomysql/connection.py", line 683, in _read_query_result
    await result.read()
  File "/root/kimi-dev/telegram-moderation-bot/venv/lib/python3.10/site-packages/aiomysql/connection.py", line 1164, in read
    first_packet = await self.connection._read_packet()
  File "/root/kimi-dev/telegram-moderation-bot/venv/lib/python3.10/site-packages/aiomysql/connection.py", line 652, in _read_packet
    packet.raise_for_error()
  File "/root/kimi-dev/telegram-moderation-bot/venv/lib/python3.10/site-packages/pymysql/protocol.py", line 219, in raise_for_error
    err.raise_mysql_exception(self._data)
  File "/root/kimi-dev/telegram-moderation-bot/venv/lib/python3.10/site-packages/pymysql/err.py", line 150, in raise_mysql_exception
    raise errorclass(errno, errval)
pymysql.err.OperationalError: (1054, "Unknown column 'rule_group_id' in 'where clause'")
[ERROR] 2025-02-12 15:02:49,230 - member_system_logger - ERROR - 查询出错: 
        SELECT * FROM chats
        WHERE rule_group_id = %s
        ORDER BY created_at DESC
        , (1054, "Unknown column 'rule_group_id' in 'where clause'")
Traceback (most recent call last):
  File "/root/kimi-dev/telegram-moderation-bot/src/core/database/db/base_database.py", line 97, in fetch_all
    await cursor.execute(sql, params)
  File "/root/kimi-dev/telegram-moderation-bot/venv/lib/python3.10/site-packages/aiomysql/cursors.py", line 239, in execute
    await self._query(query)
  File "/root/kimi-dev/telegram-moderation-bot/venv/lib/python3.10/site-packages/aiomysql/cursors.py", line 457, in _query
    await conn.query(q)
  File "/root/kimi-dev/telegram-moderation-bot/venv/lib/python3.10/site-packages/aiomysql/connection.py", line 469, in query
    await self._read_query_result(unbuffered=unbuffered)
  File "/root/kimi-dev/telegram-moderation-bot/venv/lib/python3.10/site-packages/aiomysql/connection.py", line 683, in _read_query_result
    await result.read()
  File "/root/kimi-dev/telegram-moderation-bot/venv/lib/python3.10/site-packages/aiomysql/connection.py", line 1164, in read
    first_packet = await self.connection._read_packet()
  File "/root/kimi-dev/telegram-moderation-bot/venv/lib/python3.10/site-packages/aiomysql/connection.py", line 652, in _read_packet
    packet.raise_for_error()
  File "/root/kimi-dev/telegram-moderation-bot/venv/lib/python3.10/site-packages/pymysql/protocol.py", line 219, in raise_for_error
    err.raise_mysql_exception(self._data)
  File "/root/kimi-dev/telegram-moderation-bot/venv/lib/python3.10/site-packages/pymysql/err.py", line 150, in raise_mysql_exception
    raise errorclass(errno, errval)
pymysql.err.OperationalError: (1054, "Unknown column 'rule_group_id' in 'where clause'")
[ERROR] 2025-02-12 15:02:55,955 - member_system_logger - ERROR - 查询出错: 
        SELECT * FROM chats
        WHERE rule_group_id = %s
        ORDER BY created_at DESC
        , (1054, "Unknown column 'rule_group_id' in 'where clause'")
Traceback (most recent call last):
  File "/root/kimi-dev/telegram-moderation-bot/src/core/database/db/base_database.py", line 97, in fetch_all
    await cursor.execute(sql, params)
  File "/root/kimi-dev/telegram-moderation-bot/venv/lib/python3.10/site-packages/aiomysql/cursors.py", line 239, in execute
    await self._query(query)
  File "/root/kimi-dev/telegram-moderation-bot/venv/lib/python3.10/site-packages/aiomysql/cursors.py", line 457, in _query
    await conn.query(q)
  File "/root/kimi-dev/telegram-moderation-bot/venv/lib/python3.10/site-packages/aiomysql/connection.py", line 469, in query
    await self._read_query_result(unbuffered=unbuffered)
  File "/root/kimi-dev/telegram-moderation-bot/venv/lib/python3.10/site-packages/aiomysql/connection.py", line 683, in _read_query_result
    await result.read()
  File "/root/kimi-dev/telegram-moderation-bot/venv/lib/python3.10/site-packages/aiomysql/connection.py", line 1164, in read
    first_packet = await self.connection._read_packet()
  File "/root/kimi-dev/telegram-moderation-bot/venv/lib/python3.10/site-packages/aiomysql/connection.py", line 652, in _read_packet
    packet.raise_for_error()
  File "/root/kimi-dev/telegram-moderation-bot/venv/lib/python3.10/site-packages/pymysql/protocol.py", line 219, in raise_for_error
    err.raise_mysql_exception(self._data)
  File "/root/kimi-dev/telegram-moderation-bot/venv/lib/python3.10/site-packages/pymysql/err.py", line 150, in raise_mysql_exception
    raise errorclass(errno, errval)
pymysql.err.OperationalError: (1054, "Unknown column 'rule_group_id' in 'where clause'")
[ERROR] 2025-02-12 15:13:20,185 - member_system_logger - ERROR - 查询出错: 
        SELECT * FROM chats
        WHERE rule_group_id = %s
        ORDER BY created_at DESC
        , (1054, "Unknown column 'rule_group_id' in 'where clause'")
Traceback (most recent call last):
  File "/root/kimi-dev/telegram-moderation-bot/src/core/database/db/base_database.py", line 97, in fetch_all
    await cursor.execute(sql, params)
  File "/root/kimi-dev/telegram-moderation-bot/venv/lib/python3.10/site-packages/aiomysql/cursors.py", line 239, in execute
    await self._query(query)
  File "/root/kimi-dev/telegram-moderation-bot/venv/lib/python3.10/site-packages/aiomysql/cursors.py", line 457, in _query
    await conn.query(q)
  File "/root/kimi-dev/telegram-moderation-bot/venv/lib/python3.10/site-packages/aiomysql/connection.py", line 469, in query
    await self._read_query_result(unbuffered=unbuffered)
  File "/root/kimi-dev/telegram-moderation-bot/venv/lib/python3.10/site-packages/aiomysql/connection.py", line 683, in _read_query_result
    await result.read()
  File "/root/kimi-dev/telegram-moderation-bot/venv/lib/python3.10/site-packages/aiomysql/connection.py", line 1164, in read
    first_packet = await self.connection._read_packet()
  File "/root/kimi-dev/telegram-moderation-bot/venv/lib/python3.10/site-packages/aiomysql/connection.py", line 652, in _read_packet
    packet.raise_for_error()
  File "/root/kimi-dev/telegram-moderation-bot/venv/lib/python3.10/site-packages/pymysql/protocol.py", line 219, in raise_for_error
    err.raise_mysql_exception(self._data)
  File "/root/kimi-dev/telegram-moderation-bot/venv/lib/python3.10/site-packages/pymysql/err.py", line 150, in raise_mysql_exception
    raise errorclass(errno, errval)
pymysql.err.OperationalError: (1054, "Unknown column 'rule_group_id' in 'where clause'")
[ERROR] 2025-02-12 15:14:00,271 - member_system_logger - ERROR - 查询出错: 
        SELECT * FROM chats
        WHERE rule_group_id = %s
        ORDER BY created_at DESC
        , (1054, "Unknown column 'rule_group_id' in 'where clause'")
Traceback (most recent call last):
  File "/root/kimi-dev/telegram-moderation-bot/src/core/database/db/base_database.py", line 97, in fetch_all
    await cursor.execute(sql, params)
  File "/root/kimi-dev/telegram-moderation-bot/venv/lib/python3.10/site-packages/aiomysql/cursors.py", line 239, in execute
    await self._query(query)
  File "/root/kimi-dev/telegram-moderation-bot/venv/lib/python3.10/site-packages/aiomysql/cursors.py", line 457, in _query
    await conn.query(q)
  File "/root/kimi-dev/telegram-moderation-bot/venv/lib/python3.10/site-packages/aiomysql/connection.py", line 469, in query
    await self._read_query_result(unbuffered=unbuffered)
  File "/root/kimi-dev/telegram-moderation-bot/venv/lib/python3.10/site-packages/aiomysql/connection.py", line 683, in _read_query_result
    await result.read()
  File "/root/kimi-dev/telegram-moderation-bot/venv/lib/python3.10/site-packages/aiomysql/connection.py", line 1164, in read
    first_packet = await self.connection._read_packet()
  File "/root/kimi-dev/telegram-moderation-bot/venv/lib/python3.10/site-packages/aiomysql/connection.py", line 652, in _read_packet
    packet.raise_for_error()
  File "/root/kimi-dev/telegram-moderation-bot/venv/lib/python3.10/site-packages/pymysql/protocol.py", line 219, in raise_for_error
    err.raise_mysql_exception(self._data)
  File "/root/kimi-dev/telegram-moderation-bot/venv/lib/python3.10/site-packages/pymysql/err.py", line 150, in raise_mysql_exception
    raise errorclass(errno, errval)
pymysql.err.OperationalError: (1054, "Unknown column 'rule_group_id' in 'where clause'")
[ERROR] 2025-02-13 05:48:45,104 - member_system_logger - ERROR - 查询出错: 
        SELECT * FROM chats
        WHERE rule_group_id IS NULL
        AND WHERE user_id = %s
        ORDER BY created_at DESC
        , (1064, "You have an error in your SQL syntax; check the manual that corresponds to your MySQL server version for the right syntax to use near 'WHERE user_id = 5809832805\n        ORDER BY created_at DESC' at line 3")
Traceback (most recent call last):
  File "/root/kimi-dev/telegram-moderation-bot/src/core/database/db/base_database.py", line 97, in fetch_all
    await cursor.execute(sql, params)
  File "/root/kimi-dev/telegram-moderation-bot/venv/lib/python3.10/site-packages/aiomysql/cursors.py", line 239, in execute
    await self._query(query)
  File "/root/kimi-dev/telegram-moderation-bot/venv/lib/python3.10/site-packages/aiomysql/cursors.py", line 457, in _query
    await conn.query(q)
  File "/root/kimi-dev/telegram-moderation-bot/venv/lib/python3.10/site-packages/aiomysql/connection.py", line 469, in query
    await self._read_query_result(unbuffered=unbuffered)
  File "/root/kimi-dev/telegram-moderation-bot/venv/lib/python3.10/site-packages/aiomysql/connection.py", line 683, in _read_query_result
    await result.read()
  File "/root/kimi-dev/telegram-moderation-bot/venv/lib/python3.10/site-packages/aiomysql/connection.py", line 1164, in read
    first_packet = await self.connection._read_packet()
  File "/root/kimi-dev/telegram-moderation-bot/venv/lib/python3.10/site-packages/aiomysql/connection.py", line 652, in _read_packet
    packet.raise_for_error()
  File "/root/kimi-dev/telegram-moderation-bot/venv/lib/python3.10/site-packages/pymysql/protocol.py", line 219, in raise_for_error
    err.raise_mysql_exception(self._data)
  File "/root/kimi-dev/telegram-moderation-bot/venv/lib/python3.10/site-packages/pymysql/err.py", line 150, in raise_mysql_exception
    raise errorclass(errno, errval)
pymysql.err.ProgrammingError: (1064, "You have an error in your SQL syntax; check the manual that corresponds to your MySQL server version for the right syntax to use near 'WHERE user_id = 5809832805\n        ORDER BY created_at DESC' at line 3")
